[2023-10-07T11:14:16.056+0000] {taskinstance.py:1159} INFO - Dependencies all met for dep_context=non-requeueable deps ti=<TaskInstance: networkrail_movements_to_gcs_and_then_bigquery.load_data_to_gcs backfill__2023-09-08T00:00:00+00:00 [queued]>
[2023-10-07T11:14:16.068+0000] {taskinstance.py:1159} INFO - Dependencies all met for dep_context=requeueable deps ti=<TaskInstance: networkrail_movements_to_gcs_and_then_bigquery.load_data_to_gcs backfill__2023-09-08T00:00:00+00:00 [queued]>
[2023-10-07T11:14:16.068+0000] {taskinstance.py:1361} INFO - Starting attempt 3 of 3
[2023-10-07T11:14:16.092+0000] {taskinstance.py:1382} INFO - Executing <Task(PythonOperator): load_data_to_gcs> on 2023-09-08 00:00:00+00:00
[2023-10-07T11:14:16.099+0000] {standard_task_runner.py:57} INFO - Started process 78667 to run task
[2023-10-07T11:14:16.105+0000] {standard_task_runner.py:84} INFO - Running: ['***', 'tasks', 'run', 'networkrail_movements_to_gcs_and_then_bigquery', 'load_data_to_gcs', 'backfill__2023-09-08T00:00:00+00:00', '--job-id', '75', '--pool', 'default_pool', '--raw', '--subdir', 'DAGS_FOLDER/networkrail_movements_to_gcs_and_then_bigquery.py', '--cfg-path', '/tmp/tmppq79_q2l']
[2023-10-07T11:14:16.106+0000] {standard_task_runner.py:85} INFO - Job 75: Subtask load_data_to_gcs
[2023-10-07T11:14:16.209+0000] {task_command.py:415} INFO - Running <TaskInstance: networkrail_movements_to_gcs_and_then_bigquery.load_data_to_gcs backfill__2023-09-08T00:00:00+00:00 [running]> on host 6b4be57cca48
[2023-10-07T11:14:16.349+0000] {taskinstance.py:1660} INFO - Exporting env vars: AIRFLOW_CTX_DAG_OWNER='Skooldio' AIRFLOW_CTX_DAG_ID='networkrail_movements_to_gcs_and_then_bigquery' AIRFLOW_CTX_TASK_ID='load_data_to_gcs' AIRFLOW_CTX_EXECUTION_DATE='2023-09-08T00:00:00+00:00' AIRFLOW_CTX_TRY_NUMBER='3' AIRFLOW_CTX_DAG_RUN_ID='backfill__2023-09-08T00:00:00+00:00'
[2023-10-07T11:14:16.483+0000] {taskinstance.py:1943} ERROR - Task failed with exception
Traceback (most recent call last):
  File "/home/airflow/.local/lib/python3.8/site-packages/google/cloud/storage/blob.py", line 2540, in upload_from_file
    created_json = self._do_upload(
  File "/home/airflow/.local/lib/python3.8/site-packages/google/cloud/storage/blob.py", line 2355, in _do_upload
    response = self._do_multipart_upload(
  File "/home/airflow/.local/lib/python3.8/site-packages/google/cloud/storage/blob.py", line 1890, in _do_multipart_upload
    response = upload.transmit(
  File "/home/airflow/.local/lib/python3.8/site-packages/google/resumable_media/requests/upload.py", line 153, in transmit
    return _request_helpers.wait_and_retry(
  File "/home/airflow/.local/lib/python3.8/site-packages/google/resumable_media/requests/_request_helpers.py", line 155, in wait_and_retry
    response = func()
  File "/home/airflow/.local/lib/python3.8/site-packages/google/resumable_media/requests/upload.py", line 149, in retriable_request
    self._process_response(result)
  File "/home/airflow/.local/lib/python3.8/site-packages/google/resumable_media/_upload.py", line 114, in _process_response
    _helpers.require_status_code(response, (http.client.OK,), self._get_status_code)
  File "/home/airflow/.local/lib/python3.8/site-packages/google/resumable_media/_helpers.py", line 108, in require_status_code
    raise common.InvalidResponse(
google.resumable_media.common.InvalidResponse: ('Request failed with status code', 403, 'Expected one of', 200)

During handling of the above exception, another exception occurred:

Traceback (most recent call last):
  File "/home/airflow/.local/lib/python3.8/site-packages/airflow/operators/python.py", line 192, in execute
    return_value = self.execute_callable()
  File "/home/airflow/.local/lib/python3.8/site-packages/airflow/operators/python.py", line 209, in execute_callable
    return self.python_callable(*self.op_args, **self.op_kwargs)
  File "/opt/airflow/dags/networkrail_movements_to_gcs_and_then_bigquery.py", line 120, in _load_data_to_gcs
    blob.upload_from_filename(file_path)
  File "/home/airflow/.local/lib/python3.8/site-packages/google/cloud/storage/blob.py", line 2684, in upload_from_filename
    self.upload_from_file(
  File "/home/airflow/.local/lib/python3.8/site-packages/google/cloud/storage/blob.py", line 2557, in upload_from_file
    _raise_from_invalid_response(exc)
  File "/home/airflow/.local/lib/python3.8/site-packages/google/cloud/storage/blob.py", line 4373, in _raise_from_invalid_response
    raise exceptions.from_http_status(response.status_code, message, response=response)
google.api_core.exceptions.Forbidden: 403 POST https://storage.googleapis.com/upload/storage/v1/b/chaphowasit-project-network_rail/o?uploadType=multipart: {
  "error": {
    "code": 403,
    "message": "gcstobigquery@essential-graph-395008.iam.gserviceaccount.com does not have storage.objects.create access to the Google Cloud Storage object. Permission 'storage.objects.create' denied on resource (or it may not exist).",
    "errors": [
      {
        "message": "gcstobigquery@essential-graph-395008.iam.gserviceaccount.com does not have storage.objects.create access to the Google Cloud Storage object. Permission 'storage.objects.create' denied on resource (or it may not exist).",
        "domain": "global",
        "reason": "forbidden"
      }
    ]
  }
}
: ('Request failed with status code', 403, 'Expected one of', <HTTPStatus.OK: 200>)
[2023-10-07T11:14:16.491+0000] {taskinstance.py:1400} INFO - Marking task as FAILED. dag_id=networkrail_movements_to_gcs_and_then_bigquery, task_id=load_data_to_gcs, execution_date=20230908T000000, start_date=20231007T111416, end_date=20231007T111416
[2023-10-07T11:14:16.506+0000] {standard_task_runner.py:104} ERROR - Failed to execute job 75 for task load_data_to_gcs (403 POST https://storage.googleapis.com/upload/storage/v1/b/chaphowasit-project-network_rail/o?uploadType=multipart: {
  "error": {
    "code": 403,
    "message": "gcstobigquery@essential-graph-395008.iam.gserviceaccount.com does not have storage.objects.create access to the Google Cloud Storage object. Permission 'storage.objects.create' denied on resource (or it may not exist).",
    "errors": [
      {
        "message": "gcstobigquery@essential-graph-395008.iam.gserviceaccount.com does not have storage.objects.create access to the Google Cloud Storage object. Permission 'storage.objects.create' denied on resource (or it may not exist).",
        "domain": "global",
        "reason": "forbidden"
      }
    ]
  }
}
: ('Request failed with status code', 403, 'Expected one of', <HTTPStatus.OK: 200>); 78667)
[2023-10-07T11:14:16.522+0000] {local_task_job_runner.py:228} INFO - Task exited with return code 1
[2023-10-07T11:14:16.539+0000] {taskinstance.py:2784} INFO - 0 downstream tasks scheduled from follow-on schedule check
